# 0x11 错误、调试和测试

[TOC]

## 1. Errors and Exceptions

Errors and Exceptions 都是 class。因此捕获的异常/错误，其实就是在捕获相应的实例。

### Errors

-   Syntax Errors 也称作 parsing errors。

```
>>> while True print('Hello world')
  File "<stdin>", line 1, in ?
    while True print('Hello world')
                   ^
SyntaxError: invalid syntax
```

-   NameError

若将 print 误拼为 Print ，会产生 NameError。

```
>>> Print("Hello World")
Traceback (most recent call last):
  File "<stdin>", line 1, in <module>
NameError: name 'Print' is not defined
>>> print("Hello World")
Hello World
```

### Exceptions

标准异常的名称是内建标识符，不是保留关键字。

即便某条语句或表达式在语法上完全正确的，但在尝试执行该语句或表达式时也可能引发 *error*。
在执行期间检测到的 *error* 称为 异常 *exceptions* ，异常并不会无条件的导致程序奔溃。
In the Python world, runtime errors are called exceptions. 
库参考中的 Built-in Exceptions[¶](https://docs.python.org/3/library/exceptions.html#built-in-exceptions) 列出了内建异常及其含义。

比如，从网络抓取数据时，网络突然断线便会产生异常。
当尝试读取输入时，按下 `[ctrl-d]`, (或在windows下按下 `[ctrl-z]` )，会触发异常。

```shell
>>> s = input('Enter something --> ')
Enter something --> Traceback (most recent call last):
  File "<stdin>", line 1, in <module>
EOFError
```

EOFError - end of file Error：是内建异常名称，表示 python 在没有预料的情况下，捕获了 *end of file* symbol 

### 异常类型

异常类型也是 class，所有错误类型都继承自`BaseException` 。
因此 `except` 在捕获某错误类型的同时，还会捕获其派生出的子类。

```
try:
    foo()
except ValueError as e:
    print('ValueError')
except UnicodeError as e:
    print('UnicodeError')
```

`except UnicodeError as e:` 永远捕获不到 `UnicodeError` 。
应为`UnicodeError` 是 `ValueError` 的子类，会被第一个 `except` 捕获。

Python所有的错误都是从`BaseException`类派生的，常见的错误类型和继承关系看这里：[Exception hierarchy](https://docs.python.org/3/library/exceptions.html#exception-hierarchy)

```
LookupError: value does not appear in the dictionary
```

### 定义异常

Errors 和 Exceptions 都是 class，它们都直接或间接的继承自 `Exception` 类。
也可在异常类中定义其它类中包含的行为。
但是为了保持简洁，通常只会提供一些属性。
这些属性允许通过 handlers 为异常提取 error 信息。

当需要创建一个可以抛出不同错误的模块时，常见的做法是为该模块中需要定义的异常先创建一个基类。然后再为不同的错误条件创建特定的异常子类：

```
class Error(Exception):
    """Base class for exceptions in this module."""
    # 此模块中异常的基类。
    pass

class InputError(Error):
    """Exception raised for errors in the input. 输入中的错误引发的异常

    Attributes:
        expression -- input expression in which the error occurred 在输入表达式中发生的错误
        message -- explanation of the error 错误解释
    """

    def __init__(self, expression, message):
        self.expression = expression
        self.message = message

class TransitionError(Error):
    """Raised when an operation attempts a state transition that's not
    allowed.在操作尝试不允许的状态转换时引发。

    Attributes:属性
        previous -- state at beginning of transition 开始转换时的状态
        next -- attempted new state 尝试新的状态
        message -- explanation of why the specific transition is not allowed 说明为什么指定的转换是不允许的
    """

    def __init__(self, previous, next, message):
        self.previous = previous
        self.next = next
        self.message = message
```

与标准异常名类似，大多数异常名的命名都以 “Error” 结尾。
大多数标准模块都定义了自己的异常，用于报告在它们所定义的函数中可能发生的错误。

```
>>> class MyError(Exception):
...     def __init__(self, value):
...         self.value = value
...     def __str__(self):
...         return repr(self.value)
...
>>> try:
...     raise MyError(2*2)
... except MyError as e:
...     print('My exception occurred, value:', e.value)
...
My exception occurred, value: 4

>>> raise MyError('oops!')
Traceback (most recent call last):
  File "<stdin>", line 1, in ?
__main__.MyError: 'oops!'
```

本示例将 `Exception` 默认的 `__init__()` 进行了覆盖。
新行为仅创建了 value 属性。
这会替换了默认创建 *args* 属性的行为。

### 抛出异常

`raise` 允许程序员强制抛出指定异常。
`raise` 语句如果不带参数，就会把当前错误原样抛出。

```
>>> raise NameError('HiThere')
Traceback (most recent call last):
  File "<stdin>", line 1, in ?
NameError: HiThere
```

传递给 [`raise`](../reference/simple_stmts.html#raise) 的参数表示需要抛出的异常。
该参数必须是一个**异常实例**或**异常类**( 继承自 [`Exception`](../library/exceptions.html#Exception) 的类)。
如果将**异常类**作为参数，则会调用该异常类的无参数 constructor ，以暗中将该类实例化。

```
raise ValueError  # shorthand for 'raise ValueError()'

>>> raise ValueError
Traceback (most recent call last):
  File "<pyshell#10>", line 1, in <module>
    raise ValueError
ValueError
```

如果只是想确定异常是否被抛出，但并不打算处理该异常。
同样可使用 [`raise`](../reference/simple_stmts.html#raise)  将该异常重新抛出。
此时，捕获错误的目的只是记录，便于后续追踪。

```
>>> try:
...     raise NameError('HiThere')
... except NameError:
...     print('An exception flew by!')
...     raise
...
An exception flew by!
Traceback (most recent call last):
  File "<stdin>", line 2, in ?
NameError: HiThere
```

通过 `raise` 可以进行异常类型的转换：

```
try:
    10 / 0
except ZeroDivisionError:
    raise ValueError('input error!')
```

#### 异常参数

异常可能含有异常参数 (exception’s *argument* )，异常类型决定了 argument 的存在和它的类型。

```
try:
    x = int(input("Please enter a number: "))
except ValueError as exc_arg: # 用户中断程序时，会触发异常
    print(exc_arg)
    print(exc_arg.args)

'''
输出：
Please enter a number: string
invalid literal for int() with base 10: 'string'
("invalid literal for int() with base 10: 'string'",)
'''     
```

在 `except` 从句中，为 `ValueError` 指定了 `exc_arg` 变量。该变量被绑定到异常的实例，该实例的异常参数被存储在 `instance.args` 中。
注意，异常实例中已经定义了 `__str__` 方法，因此异常参数可通过实例名直接打印( 无需引用 `.args` 域 )。

还可以在异常抛出前，先将某个异常实例化，并根据需要向其添加任何属性。

```
try:
    raise Exception('spam', 'eggs')
except Exception as inst:
    print(type(inst))    # the exception instance
    print(inst.args)     # arguments stored in .args
    print(inst)          # __str__ allows args to be printed directly,
    # but may be overridden覆盖 in exception subclasses
    x, y = inst.args     # unpack args
    print('x =', x)
    print('y =', y)
    
<class 'Exception'>
('spam', 'eggs')
('spam', 'eggs')
x = spam
y = eggs
```

假如，某个异常实例含有异常参数，但该实例并未被 `except` 进行处理。此时会由 Python 直接进行处理，并在最后打印出异常参数。

```
In [1]: raise Exception('spam', 'eggs')
---------------------------------------------------------------------------
Exception               Traceback (most recent call last)
<ipython-input-1-7d5441f51367> in <module>()
----> 1 raise Exception('spam', 'eggs')

Exception: ('spam', 'eggs')
```

### logging.exception( )

记录 Traceback 中的信息。

logging.exception(*msg*, \*args, \*\*kwargs)

Logs a message with level `ERROR` on the root logger. The arguments are interpreted as for [`debug()`](https://docs.python.org/3/library/logging.html#logging.debug). Exception info is added to the logging message. This function should only be called from an exception handler.

-   Help on function exception in module logging:

    exception(msg, \*args, exc_info=True, \*\*kwargs)

    Log a message with severity 'ERROR' on the root logger, with exception information. If the logger has no handlers, basicConfig() is called to add a console handler with a pre-defined format.

如果没有对异常进行处理，该异常会被认为是一个未处理异常，此时由 Python 直接进行处理，Python 会停止执行程序并给出提示信息。

如果想要看到 Traceback，但又不想退出程序 。
可使用 `logging.exception()` ，该方法可以把错误堆栈打印出来，同时让程序继续执行下去。

通过配置，`logging`还可以把错误记录到日志文件里，方便事后排查。

```
# err_logging.py

import logging

def foo(s):
    return 10 / int(s)

def bar(s):
    return foo(s) * 2

def main():
    try:
        bar('0')
    except Exception as e:
        logging.exception(e)

main()
print('END')
```

同样是出错，但程序打印完错误信息后会继续执行，并正常退出：

```
$ python3 err_logging.py
ERROR:root:division by zero
Traceback (most recent call last):
  File "err_logging.py", line 13, in main
    bar('0')
  File "err_logging.py", line 9, in bar
    return foo(s) * 2
  File "err_logging.py", line 6, in foo
    return 10 / int(s)
ZeroDivisionError: division by zero
END
```





## 2. 处理异常

Handling Exceptions

### 约定错误代码

可以事先为程序运行期间可能出现的错误类型约定好各自的错误代码。
当出现相应错误代码时，便可有效判断错误原因。
比如，操作系统提供的调用中，便会返回错误代码。
又如，`open()` 函数成功打开文件时，会返回文件描述符(一个整数)，出错时返回 -1.

缺点：函数的正常返回值可能同错误代码混淆。这使得调用者需使用大量代码来判断是否出错。

```
def foo():
    r = some_function()
    if r==(-1):
        return (-1)
    # do something
    return r

def bar():
    r = foo()
    if r==(-1):
        print('Error')
    else:
        pass
```



### try...except

注意：有时候一些需要逻辑判断的部分，也可用异常处理直接跳过，把所有不符合目标项全部当作异常处理。比如分拆字符串时，如果遇到不复合条件的字符串，可以直接当作异常处理，避免用复杂的逻辑处理所有所有可能出现的非标准格式。

```
# 持续请求用户输入，直到捕获一个有效的整数
while True:
    try:
        x = int(input("Please enter a number: "))
        break
    except ValueError: # 用户中断程序时，会触发异常
        print("Oops!  That was no valid number.  Try again")   
# 使用 control-c 会触发KeyboardInterrupt
```

-   首先执行 `try` 子句， `try` 从句至少关联一个 `except` 从句

-   如果没有发生异常，`except` 被忽略；

-   如果在 `try` 子句执行期间发生异常，`try` 中剩余的代码被跳过，直接执行 `except` 语句：
    -   如果 `except` 中的异常名和引发异常的类型相匹配，相应 `except` 子句会被执行。

        -   `try` 语句可拥有多个 `except` 从句，用于为不同的异常类型指定相应的处理器。但是，最多只有一个处理器被执行。

        -   `except` 子句可用元组指定多个异常名，例如

            ```
            except (RuntimeError, TypeError, NameError):
            	pass
            ```

-   如果异常发生时，在 except 子句中没有相匹配的异常名，该异常会被传递到 `try` 语句之外，并沿着调用链向上传递，直到异常成功被处理为止。如果始终没有发现相应的处理器，该异常被认为是一个未处理异常，此时由 Python 直接进行处理，Python 会停止执行程序并给出提示信息。

-   若 `except` 中完全没有提供任何错误/异常的名称，将会处理所有的错误和异常。这种方法很可能会掩盖真正的编程错误。

    ```
    import sys

    try:
        f = open('myfile.txt')
        s = f.readline()
        i = int(s.strip())
    except OSError as err:
        print("OS error: {0}".format(err))
    except ValueError:
        print("Could not convert data to an integer.")
    except:
        print("Unexpected error:", sys.exc_info()[0])
    raise  # 向上抛出错误，供调用者使用
    ```

下面的示例中，如果出现 `IOError` ，那么引发错误的详细信息将被存放在对象 `e` 中。 


```
try:
    f = open("file.txt", 'r')
except IOError as e:
    print(e)
```

#### finally

注意，无论是否发生错误，`finally` 总会被执行。
也可以没有 `finally` 从句。

#### else

若在 `except` 语句块后面跟一个 `else` 语句块。
那么当没有错误发生时，便会自动执行 `else` 中的语句。

```
try:
    print('try...')
    r = 10 / int('2')
    print('result:', r)
except ValueError as e:
    print('ValueError:', e)
except ZeroDivisionError as e:
    print('ZeroDivisionError:', e)
else:
    print('no error!')
finally:
    print('finally...')
print('END')
```

使用 `else` 子句添加额外代码的方式，比直接在 `try` 子句中添加更好。因为这可以保证额外的代码引发的异常不是由 [`try`](../reference/compound_stmts.html#try) ... [`except`](../reference/compound_stmts.html#except) 语句保护的代码块引发的。

#### 处理间接调用

异常处理器同样会对 “间接调用” 过程中产生的异常进行处理。
比如，当调用 `tyr` 外部的函数时，若此函数引发了异常，也会对其进行处理。

```
>>> def this_fails():
...     x = 1/0
...
>>> try:
...     this_fails()
... except ZeroDivisionError as err:
...     print('Handling run-time error:', err)
...
Handling run-time error: int division or modulo by zero
```

下面来看一个跨越多层的间接调用，这是只要 `main()` 能够俘获到异常，便可进行处理。

```
def foo(s):
    return 10 / int(s)

def bar(s):
    return foo(s) * 2

def main():
    try:
        bar('0')
    except Exception as e:
        print('Error:', e)
    finally:
        print('finally...')
```

因此，不需要在每个可能出错的地方去捕获错误，只要在合适的层次去捕获错误就可以了。这样便可减少了写 `try...except...finally` 的麻烦。

#### 异常类型的兼容关系

如果 "A: [`except`](https://docs.python.org/3/reference/compound_stmts.html#except) " 子句捕获错误类型 x ；"B: [`except`](https://docs.python.org/3/reference/compound_stmts.html#except) " 子句捕获错误类型 super_x。(x 是 super_x 的子类)。
那么，"B: [`except`](https://docs.python.org/3/reference/compound_stmts.html#except) " 也会捕获错误类型 x，但是 "A: [`except`](https://docs.python.org/3/reference/compound_stmts.html#except) " 不会捕获 super_x。

```
class B(Exception):
    pass

class C(B):
    pass

class D(C):
    pass

for cls in [B, C, D]:
    try:
        raise cls()
    except D:
        print("D")
    except C:
        print("C")
    except B:
        print("B")
'''输出 B C D'''
```

注意：如果将 `except` 子句的顺序反转( 将 `except B` 放在第一位)，则会输出 B, B, B 。

### 定义清理操作 finally

Defining Clean-up Actions[¶](https://docs.python.org/3/tutorial/errors.html#defining-clean-up-actions)

无论异常是否发生，在离开 `try` statement 之前， `finally` 子句总会被执行。

>   A *finally clause* is always executed before leaving the [`try`](../reference/compound_stmts.html#try) statement, whether an exception has occurred or not. When an exception has occurred in the [`try`](../reference/compound_stmts.html#try) clause and has not been handled by an [`except`](../reference/compound_stmts.html#except) clause (or it has occurred in an [`except`](../reference/compound_stmts.html#except) or [`else`](../reference/compound_stmts.html#else) clause), it is re-raised after the [`finally`](../reference/compound_stmts.html#finally) clause has been executed. The [`finally`](../reference/compound_stmts.html#finally) clause is also executed “on the way out” when any other clause of the [`try`](../reference/compound_stmts.html#try) statement is left via a [`break`](../reference/simple_stmts.html#break), [`continue`](../reference/simple_stmts.html#continue) or [`return`](../reference/simple_stmts.html#return) statement. A more complicated example:

无论异常是否发生，*finally* 子句总是在离开 [`try`](../reference/compound_stmts.html#try) 语句之前被执行。当 [`try`](../reference/compound_stmts.html#try) 子句中发生异常，并且没有被 [`except`](../reference/compound_stmts.html#except) 子句处理（或该异常发生在  [`except`](../reference/compound_stmts.html#except) 或 [`else`](../reference/compound_stmts.html#else) 子句中），该异常会在  [`finally`](../reference/compound_stmts.html#finally) 子句执行后重新生成。   [`try`](../reference/compound_stmts.html#try) 语句的其它子句通过 [`break`](../reference/simple_stmts.html#break), [`continue`](../reference/simple_stmts.html#continue) 或 [`return`](../reference/simple_stmts.html#return) 语句退出时， [`finally`](../reference/compound_stmts.html#finally) 子句也会“在出口处”被执行。下面是一个更复杂的例子：

```
>>> def divide(x, y):
...     try:
...         result = x / y
...     except ZeroDivisionError:
...         print("division by zero!")
...     else:
...         print("result is", result)
...     finally:
...         print("executing finally clause")
...
>>> divide(2, 1)
result is 2.0
executing finally clause
>>> divide(2, 0)
division by zero!
executing finally clause
>>> divide("2", "1")
executing finally clause
Traceback (most recent call last):
  File "<stdin>", line 1, in ?
  File "<stdin>", line 3, in divide
TypeError: unsupported operand type(s) for /: 'str' and 'str'
```

>   As you can see, the [`finally`](../reference/compound_stmts.html#finally) clause is executed in any event. The [`TypeError`](../library/exceptions.html#TypeError) raised by dividing two strings is not handled by the [`except`](../reference/compound_stmts.html#except) clause and therefore re-raised after the [`finally`](../reference/compound_stmts.html#finally) clause has been executed.

如你所见， [`finally`](../reference/compound_stmts.html#finally) 在任何情况下都会执行。 [`TypeError`](../library/exceptions.html#TypeError) 在两个字符串相除时被引发， [`TypeError`](../library/exceptions.html#TypeError) 没有通过  [`except`](../reference/compound_stmts.html#except)  子句进行处理，因此在 [`finally`](../reference/compound_stmts.html#finally) 子句执行后会被重新抛出。

>   In real world applications, the [`finally`](../reference/compound_stmts.html#finally) clause is useful for releasing external resources (such as files or network connections), regardless of whether the use of the resource was successful.

在实际的应用中， [`finally`](../reference/compound_stmts.html#finally) 子句对于释放外部资源是非常有用的（例如文件或网络连接），无论资源是否被成功使用都将被释放。

```
try:
    f = open('/path/to/file', 'r')
    print(f.read())
finally:
    if f:
        f.close()
```

### 预定义清理操作 with

Predefined Clean-up Actions

`with` 语句使用了名为 context management protocol 的技术。

8.5. The [`with`](https://docs.python.org/3/reference/compound_stmts.html#with) statement[¶](https://docs.python.org/3/reference/compound_stmts.html#the-with-statement)

```
with open("myfile.txt") as f:
    for line in f:
        print(line, end="")
```

某些对象中定义了标准清理操作，以便当我们不再需要这些对象时，可负责对其进行清理。
同使用 `finally` 子句释放资源类似，`with` 提供了更加简洁的方式，并且不需要显示调用 `close()` 。`with open` 会在我们离开某文件时，自动关闭该文件。

 `with` 声明会使用一种协议，该协议会获取由 `open` 声明返回的对象，这里暂且将其称为 "thefile"。协议总会在 `with` 内部的代码块开始之前调用 `thefile.__enter__ ` ，并在内部代码块结束后调用 `thefile.__exit__  ` 。
因此可将 `finally` 子句中的代码放到 `__exit__` 中，当使用`with` 时，便会自动执行这些语句，以避免重复使用 `try..finally` 。

上下文管理是通过 `__enter__` 和 `__exit__` 实现的。

-   object.\_\_enter\_\_(self)[¶](https://docs.python.org/3/reference/datamodel.html#object.__enter__)

    >   Enter the runtime context related to this object. The [`with`](https://docs.python.org/3/reference/compound_stmts.html#with) statement will bind this method’s return value to the target(s) specified in the [`as`](https://docs.python.org/3/reference/compound_stmts.html#as) clause of the statement, if any.

    输入与该对象相关的运行时上下文。`with` 语句将该方法的返回值绑定到 `as` 子句中指定的目标上(如果存在的话)

-   object.\_\_exit\_\_(*self*, *exc_type*, *exc_value*, *traceback*)[¶](https://docs.python.org/3/reference/datamodel.html#object.__exit__)

    >   Exit the runtime context related to this object. The parameters describe the exception that caused the context to be exited. If the context was exited without an exception, all three arguments will be [`None`](https://docs.python.org/3/library/constants.html#None).
    >
    >   If an exception is supplied, and the method wishes to suppress the exception (i.e., prevent it from being propagated), it should return a true value. Otherwise, the exception will be processed normally upon exit from this method.
    >
    >   Note that [`__exit__()`](https://docs.python.org/3/reference/datamodel.html#object.__exit__) methods should not reraise the passed-in exception; this is the caller’s responsibility.

    退出与该对象相关的运行时上下文。函数的参数用于描述会导致上下文退出的异常。如果 context 在无异常的情况下退出，则接受到的三个参数的值均是 `None` 。

    如果提供了异常，并且该方法希望抑制异常（即防止它被传播），则应该返回一个真实值。 否则，退出此方法后将正常处理异常。

    注意，\_\_exit\_\_方法不应该重写传入的异常; 这是调用者的责任。

See also : [**PEP 343**](https://www.python.org/dev/peps/pep-0343) - The “with” statement
The specification, background, and examples for the Python [`with`](https://docs.python.org/3/reference/compound_stmts.html#with) statement.

下面用一个 class 实现 `__enter__` 和 `__exit__` ：

```
class Query(object):

    def __init__(self, name):
        self.name = name

    def __enter__(self):
        print('Begin')
        return self

    def __exit__(self, exc_type, exc_value, traceback):
        if exc_type:
            print('Error')
        else:
            print('End')

    def query(self):
        print('Query info about %s...' % self.name)

with Query('Bob') as q:
    q.query()
```

输出：

```
Begin
Query info about Bob...
End
```

下面这个例子展示了使用互斥锁的代码：

```
import threading

message_lock = threading.Lock()
...
with message_lock:
    messages.add(newmessage)
```

`with` 语句执行时会自动获取 `message_lock` 对象。当执行外 `with` 代码块后，锁定将被自动释放。无论 `with` 代码块内部发生了什么，这种管理都会进行。例如，如果出现一个异常，当控制离开代码块环境时将释放锁定。

`with` 语句通常只适用于与系统资源或执行环境相关的对象，如文件、连接和锁定。

#### 并联打开多个文件

`with` 语句可以并联打开多个文件：

```
with open('man_data.txt', 'w') as man_file, open('other_data.txt’, 'w’) as other_file:
	print(man, file=man_file)
    print(other, file=other_file)
```



## 3. 调试

有的bug很复杂，我们需要知道出错时，哪些变量的值是正确的，哪些变量的值是错误的，因此，需要一整套调试程序的手段来修复bug。

此外，我们也需要跟踪程序的执行，查看变量的值是否正确，这个过程称为调试。Python的pdb可以让我们以单步方式执行代码。

写程序最痛苦的事情莫过于调试，程序往往会以你意想不到的流程来运行，你期待执行的语句其实根本没有执行，这时候，就需要调试了。

虽然用IDE调试起来比较方便，但是最后你会发现，logging才是终极武器。

### 直接打印 print

使用 `print()` 直接打印相应对象：

```
def foo(s):
    n = int(s)
    print('>>> n = %d' % n)
    return 10 / n

def main():
    foo('0')

main()
```

```
$ python3 err.py
>>> n = 0
Traceback (most recent call last):
  ...
ZeroDivisionError: integer division or modulo by zero
```

### 断言 assert

The [`assert`](https://docs.python.org/3/reference/simple_stmts.html#assert) statement [¶](https://docs.python.org/3/reference/simple_stmts.html#the-assert-statement)

Assert statements are a convenient way to insert debugging assertions into a program:

```
assert_stmt ::=  "assert" expression ["," expression]
```

The simple form, `assert expression`, is equivalent to

```
if __debug__:
    if not expression: raise AssertionError
```

The extended form, `assert expression1, expression2`, is equivalent to

```
if __debug__:
    if not expression1: raise AssertionError(expression2)
```

 [`__debug__`](https://docs.python.org/3/library/constants.html#__debug__) 和 [`AssertionError`](https://docs.python.org/3/library/exceptions.html#AssertionError) 引用了相应的内置变量。
在当前实现中，正常情况下内置变量 [`__debug__`](https://docs.python.org/3/library/constants.html#__debug__) 是 `True` ，当请求 optimization 时 (command line option -O)，变为 `False` 。
当在编译过程中请求 optimization 时，当前代码生成器不会为 assert 声明发放代码。

Note that it is unnecessary to include the source code for the expression that failed in the error message; it will be displayed as part of the stack trace. 
注意，不必在错误消息中包含失败表达式的源代码; 它将作为堆栈跟踪的一部分显示。

为 [`__debug__`](https://docs.python.org/3/library/constants.html#__debug__) 赋值是非法的。内置变量的值在解释器启动时被固定。

-   `__debug__` 

    This constant常数 is true if Python was not started with an [`-O`](https://docs.python.org/3/using/cmdline.html#cmdoption-O) option. See also the [`assert`](https://docs.python.org/3/reference/simple_stmts.html#assert)statement.

    Note：The names [`None`](https://docs.python.org/3/library/constants.html#None), [`False`](https://docs.python.org/3/library/constants.html#False), [`True`](https://docs.python.org/3/library/constants.html#True) and [`__debug__`](https://docs.python.org/3/library/constants.html#__debug__) cannot be reassigned (assignments to them, even as an attribute name, raise [`SyntaxError`](https://docs.python.org/3/library/exceptions.html#SyntaxError)), so they can be considered “true” constants.

-   exception `AssertionError` 

    Raised when an `assert` statement fails.


```
def foo(s):
    n = int(s)
    assert n != 0, 'n is zero!'
    return 10 / n

foo('0')
```

输出：

```
Traceback (most recent call last):
  File "C:\Users\iwhal\Desktop\asas.py", line 7, in <module>
    foo('0')
  File "C:\Users\iwhal\Desktop\asas.py", line 3, in foo
    assert n != 0, 'n is zero!'
AssertionError: n is zero!
```

通过命令行运行 .py 时，可使用 `-O` 参数将 [`__debug__`](https://docs.python.org/3/library/constants.html#__debug__) 设为 `Flase` 。
这样就可以关闭 `assert` ：

```
$ python3 -O err.py
Traceback (most recent call last):
  ...
ZeroDivisionError: division by zero
```

关闭后，可以把所有的 `assert` 语句当成 `pass` 看待。

`assert` 语句应该谨慎使用。大多数时候，最好是捕获异常，要么处理问题，要么向用户显示错误消息，然后退出。

### logging

`logging` 模块提供了一个灵活的全功能日志系统。
其中最简单的方法是将错误日志发送到文件或 `sys.stderr` ，但不会直接抛出错误。

-   logging.`info`(*msg*, \*args, \*\*kwargs)[¶](https://docs.python.org/3/library/logging.html#logging.info)
    Logs a message with level `INFO` on the root logger. The arguments are interpreted as for [`debug()`](https://docs.python.org/3/library/logging.html#logging.debug).
-   logging.`basicConfig`(\*\*kwargs)[¶](https://docs.python.org/3/library/logging.html#logging.basicConfig)

```
import logging
logging.basicConfig(level=logging.INFO)
s = '0'
n = int(s)
logging.info('n = %d' % n)
print(10 / n)
```

输出：

```
$ python3 err.py
INFO:root:n = 0
Traceback (most recent call last):
  File "err.py", line 8, in <module>
    print(10 / n)
ZeroDivisionError: division by zero
```

`logging` 允许指定需要记录的信息的 level。有`debug`/`info`/`warning`/`error` 等 level。
在 `logging.basicConfig()` 中指定 `level=INFO` 后，会屏蔽 `logging.debug` 。
同理，指定`level=WARNING` 后，会屏蔽 `debug` / `info` 。
`logging` 的另一个好处是通过简单的配置，一条语句可以同时输出到不同的地方，比如 console 和文件。

示例：

```
import logging
logging.debug('Debugging information')
logging.info('Informational message')
logging.warning('Warning:config file %s not found', 'server.conf')
logging.error('Error occurred')
logging.critical('Critical error -- shutting down')
```

输出：

```
WARNING:root:Warning:config file server.conf not found
ERROR:root:Error occurred
CRITICAL:root:Critical error -- shutting down
```

默认情况下，`info` 和 `debug` 消息被抑制，可用于输出的信息被发送到 standard error。Other output options include routing messages through email, datagrams, sockets, or to an HTTP Server. New filters can select different routing based on message priority: DEBUG, INFO, WARNING, ERROR, and CRITICAL.

示例，Save as `stdlib_logging.py`:

```
import os
import platform
import logging

if platform.platform().startswith('Windows'):
    logging_file = os.path.join(os.getenv('HOMEDRIVE'),
                                os.getenv('HOMEPATH'),
                                'test.log')
else:
    logging_file = os.path.join(os.getenv('HOME'),
                                'test.log')

print("Logging to", logging_file)

logging.basicConfig(
    level=logging.DEBUG,
    format='%(asctime)s : %(levelname)s : %(message)s',
    filename=logging_file,
    filemode='w',
)

logging.debug("Start of the program")
logging.info("Doing something")
logging.warning("Dying now")
```

Output:

```
$ python stdlib_logging.py
Logging to /Users/swa/test.log

$ cat /Users/swa/test.log
2014-03-29 09:27:36,660 : DEBUG : Start of the program
2014-03-29 09:27:36,660 : INFO : Doing something
2014-03-29 09:27:36,660 : WARNING : Dying now
```

>   If you do not have the `cat` command, then you can just open the `test.log` file in a text editor.

假如你没有使用 `cat` 命令，那么你仅可在文本编辑器中打开  `test.log`  文件。

**How It Works**

>   We use three modules from the standard library - the `os` module for interacting with the operating system, the `platform` module for information about the platform i.e. the operating system and the `logging` module to *log* information.

我们从标准库中使用了三个模块 -  `os` 模块与系统进行交互，`platfprm` 模块提供有关平台的信息 i.e. 操作系统，`logging` 模块提供日志信息。

>   First, we check which operating system we are using by checking the string returned by `platform.platform()` (for more information, see `import platform; help(platform)`). If it is Windows, we figure out the home drive, the home folder and the filename where we want to store the information. Putting these three parts together, we get the full location of the file. For other platforms, we need to know just the home folder of the user and we get the full location of the file.

首先，我们通过检查由 `platform.platform()` 返回的字符串来检查操作系统(更多信息，请看 `import platform; help(platform)`)。假如是windows，我们找出我们想要存储信息的主驱动，主文件夹和文件名。把这三部分放在一起，我们得出该文件的完整路径。对于其它平台，我们只需要知道user的主文件夹和我们给出文件的完整路径。

>   We use the `os.path.join()` function to put these three parts of the location together. The reason to use a special function rather than just adding the strings together is because this function will ensure the full location matches the format expected by the operating system.

我们使用 `os.path.join()` 函数，将这三个位置放置在一起。使用特殊函数而不是将字符串添加在一起的原因是因为此函数将确保完整位置与操作系统预期的格式匹配。

>   We configure the `logging` module to write all the messages in a particular format to the file we have specified.

我们配置 `logging` 模块，向我们已经指定的文件中，以特定格式写入所有信息。

>   Finally, we can put messages that are either meant for debugging, information, warning or even critical messages. Once the program has run, we can check this file and we will know what happened in the program, even though no information was displayed to the user running the program.

最后，我们放置信息，可以是debugging, information, warning 或者是关键消息。一旦系统运行，我们可以检查这个文件并且我们可以知道程序中发生了什么，即使没有信息显示给运行程序的用户。

### pdb

Python Debugger

启动Python的 pdb 调试器 ，可以让程序以单步方式运行，并可随时查看运行状态。

```
# err.py
s = '0'
n = int(s)
print(10 / n)
```

然后启动：

```
$ python3 -m pdb err.py
> /Users/michael/Github/learn-python3/samples/debug/err.py(2)<module>()
-> s = '0'
```

以参数 `-m pdb` 启动后，pdb定位到下一步要执行的代码`-> s = '0'`。

命令 `l` (这个是小写的 L) 用于查看代码：

```
  (Pdb) l 
  1     # err.py
  2  -> s = '0'
  3     n = int(s)
  4     print(10 / n)
```

命令 `n` 单步执行代码：

```
(Pdb) n
> /Users/michael/Github/learn-python3/samples/debug/err.py(3)<module>()
-> n = int(s)
(Pdb) n
> /Users/michael/Github/learn-python3/samples/debug/err.py(4)<module>()
-> print(10 / n)
```

命令 `p 变量名` 来查看变量：

```
(Pdb) p s
'0'
(Pdb) p n
0
```

命令 `q` 结束调试，退出程序：

```
(Pdb) q

```

这种通过pdb在命令行调试的方法理论上是万能的，但实在是太麻烦了，如果有一千行代码，要运行到第999行得敲多少命令啊。

### pdb.set_trace()

这个方法也是用 pdb，但是不需要单步执行。
只需要`import pdb`，然后在可能出错的地方放置 `pdb.set_trace()`，进行断点设置。

```
# err.py
import pdb

s = '0'
n = int(s)
pdb.set_trace() # 运行到这里会自动暂停
print(10 / n)
```

运行代码时，程序会自动在断点处暂停并进入 pdb 调试环境。
此时可以用命令 `p` 查看变量，或者用命令`c`继续运行：

```
$ python3 err.py 
> /Users/michael/Github/learn-python3/samples/debug/err.py(7)<module>()
-> print(10 / n)
(Pdb) p n
0
(Pdb) c
Traceback (most recent call last):
  File "err.py", line 7, in <module>
    print(10 / n)
ZeroDivisionError: division by zero

```

这个方式比直接启动pdb单步调试效率要高很多，但也高不到哪去。

### IDE

如果要比较爽地设置断点、单步执行，就需要一个支持调试功能的IDE。目前比较好的Python IDE有PyCharm：

[http://www.jetbrains.com/pycharm/](http://www.jetbrains.com/pycharm/)

另外，[Eclipse](http://eclipse.org/) 加上 [pydev](http://pydev.org/) 插件也可以调试Python程序。
虽然用IDE调试起来比较方便，但是最后你会发现，logging才是终极武器。

## 4. 单元测试 unittest

单元测试是用来对一个模块、一个函数或者一个类来进行正确性检验的测试工具。
单元测试的测试用例要覆盖常用的输入组合、边界条件和异常。
单元测试可以有效地测试某个程序模块的行为，是未来重构代码的信心保证。
单元测试代码要非常简单，如果测试代码太复杂，那么测试代码本身就可能有bug。
单元测试通过了并不意味着程序就没有bug了，但是不通过程序肯定有bug。

如果对某函数的代码修改，只需要再跑一遍单元测试，如果通过，说明我们的修改不会对该函数原有的行为造成影响，如果测试不通过，说明我们的修改与原有行为不一致，要么修改代码，要么修改测试。

这种以测试为驱动的开发模式，其最大的好处就是确保一个程序模块的行为符合我们设计的测试用例。在将来修改的时候，可以极大程度地保证该模块行为仍然是正确的。

我们来编写一个 `Dict` 类，这个类的行为和 `dict` 一致，但是可以通过 field 来访问，用起来就像下面这样：

```
>>> d = Dict(a=1, b=2)
>>> d['a']
1
>>> d.a
1
```

`mydict.py` 代码如下：

```
class Dict(dict):

    def __init__(self, **kw):
        super().__init__(**kw)

    def __getattr__(self, key):
        try:
            return self[key]
        except KeyError:
            raise AttributeError(r"'Dict' object has no attribute '%s'" % key)

    def __setattr__(self, key, value):
        self[key] = value
```

### unittest 模块

`unittest` 模块用于编写测试单元：

```
# mydict_test.py
import unittest

from mydict import Dict

class TestDict(unittest.TestCase):

    def test_init(self):
        d = Dict(a=1, b='test')
        self.assertEqual(d.a, 1)
        self.assertEqual(d.b, 'test')
        self.assertTrue(isinstance(d, dict))

    def test_key(self):
        d = Dict()
        d['key'] = 'value'
        self.assertEqual(d.key, 'value')

    def test_attr(self):
        d = Dict()
        d.key = 'value'
        self.assertTrue('key' in d)
        self.assertEqual(d['key'], 'value')

    def test_keyerror(self):
        d = Dict()
        with self.assertRaises(KeyError):
            value = d['empty']

    def test_attrerror(self):
        d = Dict()
        with self.assertRaises(AttributeError):
            value = d.empty
```

编写单元测试时，我们需要编写一个测试类，从 `unittest.TestCase` 继承。

以 `test` 开头的方法就是测试方法，不以 `test` 开头的方法不被认为是测试方法，测试的时候不会被执行。

对每一类测试都需要编写一个`test_xxx()`方法。由于`unittest.TestCase`提供了很多内置的条件判断，我们只需要调用这些方法就可以断言输出是否是我们所期望的。最常用的断言就是`assertEqual()`：

```
self.assertEqual(abs(-1), 1) # 断言函数返回的结果与1相等
```

另一种重要的断言就是期待抛出指定类型的Error，比如通过`d['empty']`访问不存在的key时，断言会抛出`KeyError`：

```
with self.assertRaises(KeyError):
    value = d['empty']
```

而通过`d.empty`访问不存在的 Attribute 时，我们期待抛出`AttributeError`：

```
with self.assertRaises(AttributeError):
    value = d.empty
```

### 运行单元测试

单元测试最简单的运行方式是在 `mydict_test.py` 的最后加上两行代码：

```
if __name__ == '__main__':
    unittest.main()
```

这样就可以把 `mydict_test.py` 当做正常的python脚本运行：

```
$ python3 mydict_test.py
```

另一种方法是在命令行通过参数`-m unittest`直接运行单元测试：

```
$ python3 -m unittest mydict_test
.....
----------------------------------------------------------------------
Ran 5 tests in 0.000s

OK
```

这是推荐的做法，因为这样可以一次批量运行很多单元测试，并且，有很多工具可以自动来运行这些单元测试。

### setUp与tearDown

可以在单元测试中编写两个特殊的`setUp()`和`tearDown()`方法。
这两个方法会分别在每调用一个测试方法的前后分别被执行。

`setUp()`和`tearDown()`方法有什么用呢？设想你的测试需要启动一个数据库，这时，就可以在`setUp()`方法中连接数据库，在`tearDown()`方法中关闭数据库，这样，不必在每个测试方法中重复相同的代码：

```
class TestDict(unittest.TestCase):

    def setUp(self):
        print('setUp...')

    def tearDown(self):
        print('tearDown...')
```

可以再次运行测试看看每个测试方法调用前后是否会打印出`setUp...`和`tearDown...`。

## 5. 文档测试 doctest

`import doctest` 

doctest 非常有用，不但**可用于测试**，还可以**直接作为示例代码**。通过某些文档生成工具，就可以自动把包含doctest的注释提取出来。用户看文档的时候，同时也看到了doctest。

如果你经常阅读Python的官方文档，可以看到很多文档都有示例代码。比如[re模块](https://docs.python.org/2/library/re.html)就带了很多示例代码：

```
>>> import re
>>> m = re.search('(?<=abc)def', 'abcdef')
>>> m.group(0)
'def'
```

可以把这些示例代码在Python的交互式环境下输入并执行，结果与文档中的示例代码显示的一致。

这些代码与其他说明可以写在注释中，然后，由一些工具来自动生成文档。既然这些代码本身就可以粘贴出来直接运行，那么，可不可以自动执行写在注释中的这些代码呢？

答案是肯定的。

当我们编写注释时，如果写上这样的注释：

```
def abs(n):
    '''
    Function to get absolute value of number.

    Example:

    >>> abs(1)
    1
    >>> abs(-1)
    1
    >>> abs(0)
    0
    '''
    return n if n >= 0 else (-n)
```

无疑更明确地告诉函数的调用者该函数的期望输入和输出。

并且，Python内置的“文档测试”（doctest）模块可以直接提取注释中的代码并执行测试。

doctest严格按照Python交互式命令行的输入和输出来判断测试结果是否正确。只有测试异常的时候，可以用`...`表示中间一大段烦人的输出。

让我们用doctest来测试上次编写的`Dict`类：

```
# mydict2.py
class Dict(dict):
    '''
    Simple dict but also support access as x.y style.

    >>> d1 = Dict()
    >>> d1['x'] = 100
    >>> d1.x
    100
    >>> d1.y = 200
    >>> d1['y']
    200
    >>> d2 = Dict(a=1, b=2, c='3')
    >>> d2.c
    '3'
    >>> d2['empty']
    Traceback (most recent call last):
        ...
    KeyError: 'empty'
    >>> d2.empty
    Traceback (most recent call last):
        ...
    AttributeError: 'Dict' object has no attribute 'empty'
    '''
    def __init__(self, **kw):
        super(Dict, self).__init__(**kw)

    def __getattr__(self, key):
        try:
            return self[key]
        except KeyError:
            raise AttributeError(r"'Dict' object has no attribute '%s'" % key)

    def __setattr__(self, key, value):
        self[key] = value

if __name__=='__main__':
    import doctest
    doctest.testmod()
```

运行 `python3 mydict2.py` ：

```
$ python3 mydict2.py
```

什么输出也没有。这说明我们编写的doctest运行都是正确的。如果程序有问题，比如把`__getattr__()`方法注释掉，再运行就会报错：

```
$ python3 mydict2.py
**********************************************************************
File "/Users/michael/Github/learn-python3/samples/debug/mydict2.py", line 10, in __main__.Dict
Failed example:
    d1.x
Exception raised:
    Traceback (most recent call last):
      ...
    AttributeError: 'Dict' object has no attribute 'x'
**********************************************************************
File "/Users/michael/Github/learn-python3/samples/debug/mydict2.py", line 16, in __main__.Dict
Failed example:
    d2.c
Exception raised:
    Traceback (most recent call last):
      ...
    AttributeError: 'Dict' object has no attribute 'c'
**********************************************************************
1 items had failures:
   2 of   9 in __main__.Dict
***Test Failed*** 2 failures.

```

注意到最后 3 行代码。当模块正常导入时，doctest不会被执行。只有在命令行直接运行时，才执行doctest。所以，不必担心doctest会在非测试环境下执行。









